[2023-02-04 09:24:46,783] {taskinstance.py:1179} INFO - Dependencies all met for <TaskInstance: yandex-rates-test.insert_data manual__2023-02-04T09:24:45.365465+00:00 [queued]>
[2023-02-04 09:24:46,795] {taskinstance.py:1179} INFO - Dependencies all met for <TaskInstance: yandex-rates-test.insert_data manual__2023-02-04T09:24:45.365465+00:00 [queued]>
[2023-02-04 09:24:46,795] {taskinstance.py:1376} INFO - 
--------------------------------------------------------------------------------
[2023-02-04 09:24:46,797] {taskinstance.py:1377} INFO - Starting attempt 1 of 1
[2023-02-04 09:24:46,798] {taskinstance.py:1378} INFO - 
--------------------------------------------------------------------------------
[2023-02-04 09:24:46,816] {taskinstance.py:1397} INFO - Executing <Task(PythonOperator): insert_data> on 2023-02-04 09:24:45.365465+00:00
[2023-02-04 09:24:46,826] {standard_task_runner.py:52} INFO - Started process 11569 to run task
[2023-02-04 09:24:46,830] {standard_task_runner.py:79} INFO - Running: ['***', 'tasks', 'run', 'yandex-rates-test', 'insert_data', 'manual__2023-02-04T09:24:45.365465+00:00', '--job-id', '277', '--raw', '--subdir', 'DAGS_FOLDER/yandex_dag_test.py', '--cfg-path', '/tmp/tmp1jgveq3e', '--error-file', '/tmp/tmprxn8_tlk']
[2023-02-04 09:24:46,831] {standard_task_runner.py:80} INFO - Job 277: Subtask insert_data
[2023-02-04 09:24:46,914] {task_command.py:371} INFO - Running <TaskInstance: yandex-rates-test.insert_data manual__2023-02-04T09:24:45.365465+00:00 [running]> on host 39df186e1726
[2023-02-04 09:24:47,012] {taskinstance.py:1591} INFO - Exporting the following env vars:
AIRFLOW_CTX_DAG_OWNER=***
AIRFLOW_CTX_DAG_ID=yandex-rates-test
AIRFLOW_CTX_TASK_ID=insert_data
AIRFLOW_CTX_EXECUTION_DATE=2023-02-04T09:24:45.365465+00:00
AIRFLOW_CTX_TRY_NUMBER=1
AIRFLOW_CTX_DAG_RUN_ID=manual__2023-02-04T09:24:45.365465+00:00
[2023-02-04 09:24:47,025] {taskinstance.py:1909} ERROR - Task failed with exception
Traceback (most recent call last):
  File "/home/airflow/.local/lib/python3.7/site-packages/airflow/operators/python.py", line 171, in execute
    return_value = self.execute_callable()
  File "/home/airflow/.local/lib/python3.7/site-packages/airflow/operators/python.py", line 189, in execute_callable
    return self.python_callable(*self.op_args, **self.op_kwargs)
  File "/opt/airflow/dags/yandex_dag_test.py", line 75, in insert_data
    print("rate_date: ", results["rate_date"])
TypeError: 'NoneType' object is not subscriptable
[2023-02-04 09:24:47,037] {taskinstance.py:1420} INFO - Marking task as FAILED. dag_id=yandex-rates-test, task_id=insert_data, execution_date=20230204T092445, start_date=20230204T092446, end_date=20230204T092447
[2023-02-04 09:24:47,051] {standard_task_runner.py:97} ERROR - Failed to execute job 277 for task insert_data ('NoneType' object is not subscriptable; 11569)
[2023-02-04 09:24:47,082] {local_task_job.py:156} INFO - Task exited with return code 1
[2023-02-04 09:24:47,119] {local_task_job.py:273} INFO - 0 downstream tasks scheduled from follow-on schedule check
