[2022-11-05 16:31:53,024] {taskinstance.py:1179} INFO - Dependencies all met for <TaskInstance: yandex-rates-test.sql_sensor_check manual__2022-11-05T16:31:24.557271+00:00 [queued]>
[2022-11-05 16:31:53,147] {taskinstance.py:1179} INFO - Dependencies all met for <TaskInstance: yandex-rates-test.sql_sensor_check manual__2022-11-05T16:31:24.557271+00:00 [queued]>
[2022-11-05 16:31:53,151] {taskinstance.py:1376} INFO - 
--------------------------------------------------------------------------------
[2022-11-05 16:31:53,152] {taskinstance.py:1377} INFO - Starting attempt 1 of 3
[2022-11-05 16:31:53,153] {taskinstance.py:1378} INFO - 
--------------------------------------------------------------------------------
[2022-11-05 16:31:53,227] {taskinstance.py:1397} INFO - Executing <Task(SqlSensor): sql_sensor_check> on 2022-11-05 16:31:24.557271+00:00
[2022-11-05 16:31:53,271] {standard_task_runner.py:52} INFO - Started process 5822 to run task
[2022-11-05 16:31:53,304] {standard_task_runner.py:79} INFO - Running: ['***', 'tasks', 'run', 'yandex-rates-test', 'sql_sensor_check', 'manual__2022-11-05T16:31:24.557271+00:00', '--job-id', '36', '--raw', '--subdir', 'DAGS_FOLDER/yandex_dag_test.py', '--cfg-path', '/tmp/tmp_pe44wkk', '--error-file', '/tmp/tmpwcdcpmty']
[2022-11-05 16:31:53,310] {standard_task_runner.py:80} INFO - Job 36: Subtask sql_sensor_check
[2022-11-05 16:31:54,069] {task_command.py:371} INFO - Running <TaskInstance: yandex-rates-test.sql_sensor_check manual__2022-11-05T16:31:24.557271+00:00 [running]> on host ec0dc6e942fe
[2022-11-05 16:31:54,629] {taskinstance.py:1591} INFO - Exporting the following env vars:
AIRFLOW_CTX_DAG_OWNER=***
AIRFLOW_CTX_DAG_ID=yandex-rates-test
AIRFLOW_CTX_TASK_ID=sql_sensor_check
AIRFLOW_CTX_EXECUTION_DATE=2022-11-05T16:31:24.557271+00:00
AIRFLOW_CTX_TRY_NUMBER=1
AIRFLOW_CTX_DAG_RUN_ID=manual__2022-11-05T16:31:24.557271+00:00
[2022-11-05 16:31:54,769] {base.py:68} INFO - Using connection ID 'my_db_conn' for task execution.
[2022-11-05 16:31:55,612] {sql.py:92} INFO - Poking: select count(*) from test.rates (with parameters None)
[2022-11-05 16:31:55,629] {base.py:68} INFO - Using connection ID 'my_db_conn' for task execution.
[2022-11-05 16:31:55,691] {taskinstance.py:1909} ERROR - Task failed with exception
Traceback (most recent call last):
  File "/home/airflow/.local/lib/python3.7/site-packages/airflow/sensors/base.py", line 277, in execute
    poke_return = self.poke(context)
  File "/home/airflow/.local/lib/python3.7/site-packages/airflow/sensors/sql.py", line 93, in poke
    records = hook.get_records(self.sql, self.parameters)
  File "/home/airflow/.local/lib/python3.7/site-packages/airflow/hooks/dbapi.py", line 162, in get_records
    cur.execute(sql)
psycopg2.errors.UndefinedTable: relation "test.rates" does not exist
LINE 1: select count(*) from test.rates
                             ^

[2022-11-05 16:31:55,724] {taskinstance.py:1420} INFO - Marking task as UP_FOR_RETRY. dag_id=yandex-rates-test, task_id=sql_sensor_check, execution_date=20221105T163124, start_date=20221105T163153, end_date=20221105T163155
[2022-11-05 16:31:55,753] {standard_task_runner.py:97} ERROR - Failed to execute job 36 for task sql_sensor_check (relation "test.rates" does not exist
LINE 1: select count(*) from test.rates
                             ^
; 5822)
[2022-11-05 16:31:55,831] {local_task_job.py:156} INFO - Task exited with return code 1
[2022-11-05 16:31:55,928] {local_task_job.py:273} INFO - 0 downstream tasks scheduled from follow-on schedule check
