[2022-08-16 15:31:36,177] {taskinstance.py:1179} INFO - Dependencies all met for <TaskInstance: yandex-rates-test.waiting_for_file manual__2022-08-16T15:31:08.152001+00:00 [queued]>
[2022-08-16 15:31:36,226] {taskinstance.py:1179} INFO - Dependencies all met for <TaskInstance: yandex-rates-test.waiting_for_file manual__2022-08-16T15:31:08.152001+00:00 [queued]>
[2022-08-16 15:31:36,227] {taskinstance.py:1376} INFO - 
--------------------------------------------------------------------------------
[2022-08-16 15:31:36,228] {taskinstance.py:1377} INFO - Starting attempt 1 of 1
[2022-08-16 15:31:36,229] {taskinstance.py:1378} INFO - 
--------------------------------------------------------------------------------
[2022-08-16 15:31:36,346] {taskinstance.py:1397} INFO - Executing <Task(FileSensor): waiting_for_file> on 2022-08-16 15:31:08.152001+00:00
[2022-08-16 15:31:36,395] {standard_task_runner.py:52} INFO - Started process 7204 to run task
[2022-08-16 15:31:36,441] {standard_task_runner.py:79} INFO - Running: ['***', 'tasks', 'run', 'yandex-rates-test', 'waiting_for_file', 'manual__2022-08-16T15:31:08.152001+00:00', '--job-id', '48', '--raw', '--subdir', 'DAGS_FOLDER/yandex_dag.py', '--cfg-path', '/tmp/tmp_iho6ci5', '--error-file', '/tmp/tmp5613chfb']
[2022-08-16 15:31:36,445] {standard_task_runner.py:80} INFO - Job 48: Subtask waiting_for_file
[2022-08-16 15:31:37,023] {task_command.py:371} INFO - Running <TaskInstance: yandex-rates-test.waiting_for_file manual__2022-08-16T15:31:08.152001+00:00 [running]> on host b232b3e4166c
[2022-08-16 15:31:37,440] {taskinstance.py:1591} INFO - Exporting the following env vars:
AIRFLOW_CTX_DAG_OWNER=***
AIRFLOW_CTX_DAG_ID=yandex-rates-test
AIRFLOW_CTX_TASK_ID=waiting_for_file
AIRFLOW_CTX_EXECUTION_DATE=2022-08-16T15:31:08.152001+00:00
AIRFLOW_CTX_TRY_NUMBER=1
AIRFLOW_CTX_DAG_RUN_ID=manual__2022-08-16T15:31:08.152001+00:00
[2022-08-16 15:31:37,614] {taskinstance.py:1909} ERROR - Task failed with exception
Traceback (most recent call last):
  File "/home/airflow/.local/lib/python3.7/site-packages/airflow/sensors/base.py", line 277, in execute
    poke_return = self.poke(context)
  File "/home/airflow/.local/lib/python3.7/site-packages/airflow/sensors/filesystem.py", line 55, in poke
    hook = FSHook(self.fs_conn_id)
  File "/home/airflow/.local/lib/python3.7/site-packages/airflow/hooks/filesystem.py", line 38, in __init__
    conn = self.get_connection(conn_id)
  File "/home/airflow/.local/lib/python3.7/site-packages/airflow/hooks/base.py", line 67, in get_connection
    conn = Connection.get_connection_from_secrets(conn_id)
  File "/home/airflow/.local/lib/python3.7/site-packages/airflow/models/connection.py", line 430, in get_connection_from_secrets
    raise AirflowNotFoundException(f"The conn_id `{conn_id}` isn't defined")
airflow.exceptions.AirflowNotFoundException: The conn_id `fs_default` isn't defined
[2022-08-16 15:31:37,643] {taskinstance.py:1420} INFO - Marking task as FAILED. dag_id=yandex-rates-test, task_id=waiting_for_file, execution_date=20220816T153108, start_date=20220816T153136, end_date=20220816T153137
[2022-08-16 15:31:37,722] {standard_task_runner.py:97} ERROR - Failed to execute job 48 for task waiting_for_file (The conn_id `fs_default` isn't defined; 7204)
[2022-08-16 15:31:37,803] {local_task_job.py:156} INFO - Task exited with return code 1
[2022-08-16 15:31:38,313] {local_task_job.py:273} INFO - 0 downstream tasks scheduled from follow-on schedule check
