[2022-11-05 14:44:50,703] {taskinstance.py:1179} INFO - Dependencies all met for <TaskInstance: yandex-rates-test.insert_data manual__2022-11-05T14:44:35.313541+00:00 [queued]>
[2022-11-05 14:44:50,791] {taskinstance.py:1179} INFO - Dependencies all met for <TaskInstance: yandex-rates-test.insert_data manual__2022-11-05T14:44:35.313541+00:00 [queued]>
[2022-11-05 14:44:50,792] {taskinstance.py:1376} INFO - 
--------------------------------------------------------------------------------
[2022-11-05 14:44:50,794] {taskinstance.py:1377} INFO - Starting attempt 1 of 1
[2022-11-05 14:44:50,795] {taskinstance.py:1378} INFO - 
--------------------------------------------------------------------------------
[2022-11-05 14:44:50,897] {taskinstance.py:1397} INFO - Executing <Task(PythonOperator): insert_data> on 2022-11-05 14:44:35.313541+00:00
[2022-11-05 14:44:50,949] {standard_task_runner.py:52} INFO - Started process 1951 to run task
[2022-11-05 14:44:51,018] {standard_task_runner.py:79} INFO - Running: ['***', 'tasks', 'run', 'yandex-rates-test', 'insert_data', 'manual__2022-11-05T14:44:35.313541+00:00', '--job-id', '7', '--raw', '--subdir', 'DAGS_FOLDER/yandex_dag_test.py', '--cfg-path', '/tmp/tmp2okvb6cs', '--error-file', '/tmp/tmps5pn3f_f']
[2022-11-05 14:44:51,041] {standard_task_runner.py:80} INFO - Job 7: Subtask insert_data
[2022-11-05 14:44:52,401] {task_command.py:371} INFO - Running <TaskInstance: yandex-rates-test.insert_data manual__2022-11-05T14:44:35.313541+00:00 [running]> on host ec0dc6e942fe
[2022-11-05 14:44:53,191] {taskinstance.py:1591} INFO - Exporting the following env vars:
AIRFLOW_CTX_DAG_OWNER=***
AIRFLOW_CTX_DAG_ID=yandex-rates-test
AIRFLOW_CTX_TASK_ID=insert_data
AIRFLOW_CTX_EXECUTION_DATE=2022-11-05T14:44:35.313541+00:00
AIRFLOW_CTX_TRY_NUMBER=1
AIRFLOW_CTX_DAG_RUN_ID=manual__2022-11-05T14:44:35.313541+00:00
[2022-11-05 14:44:53,199] {taskinstance.py:1909} ERROR - Task failed with exception
Traceback (most recent call last):
  File "/home/airflow/.local/lib/python3.7/site-packages/airflow/operators/python.py", line 171, in execute
    return_value = self.execute_callable()
  File "/home/airflow/.local/lib/python3.7/site-packages/airflow/operators/python.py", line 189, in execute_callable
    return self.python_callable(*self.op_args, **self.op_kwargs)
TypeError: insert_data() missing 4 required positional arguments: 'hist_date', 'data', 'rate_date', and 'value_'
[2022-11-05 14:44:53,260] {taskinstance.py:1420} INFO - Marking task as FAILED. dag_id=yandex-rates-test, task_id=insert_data, execution_date=20221105T144435, start_date=20221105T144450, end_date=20221105T144453
[2022-11-05 14:44:53,427] {standard_task_runner.py:97} ERROR - Failed to execute job 7 for task insert_data (insert_data() missing 4 required positional arguments: 'hist_date', 'data', 'rate_date', and 'value_'; 1951)
[2022-11-05 14:44:53,566] {local_task_job.py:156} INFO - Task exited with return code 1
[2022-11-05 14:44:54,707] {local_task_job.py:273} INFO - 0 downstream tasks scheduled from follow-on schedule check
