[2022-08-16 13:00:18,946] {taskinstance.py:1179} INFO - Dependencies all met for <TaskInstance: yandex-rates-test.insert_data scheduled__2022-08-16T09:00:00+00:00 [failed]>
[2022-08-16 13:00:18,948] {taskinstance.py:1179} INFO - Dependencies all met for <TaskInstance: yandex-rates-test.insert_data scheduled__2022-08-16T09:00:00+00:00 [failed]>
[2022-08-16 13:00:18,952] {taskinstance.py:1376} INFO - 
--------------------------------------------------------------------------------
[2022-08-16 13:00:18,963] {taskinstance.py:1377} INFO - Starting attempt 3 of 2
[2022-08-16 13:00:18,968] {taskinstance.py:1378} INFO - 
--------------------------------------------------------------------------------
[2022-08-16 13:00:19,010] {taskinstance.py:1397} INFO - Executing <Task(PythonOperator): insert_data> on 2022-08-16 09:00:00+00:00
[2022-08-16 13:00:19,017] {standard_task_runner.py:52} INFO - Started process 495 to run task
[2022-08-16 13:00:19,032] {standard_task_runner.py:79} INFO - Running: ['***', 'tasks', 'run', 'yandex-rates-test', 'insert_data', 'scheduled__2022-08-16T09:00:00+00:00', '--job-id', '6', '--pool', 'default_pool', '--raw', '--subdir', 'DAGS_FOLDER/yandex_dag.py', '--cfg-path', '/tmp/tmpurxma2fp', '--error-file', '/tmp/tmpx9l0nj_m']
[2022-08-16 13:00:19,033] {standard_task_runner.py:80} INFO - Job 6: Subtask insert_data
[2022-08-16 13:00:19,206] {task_command.py:371} INFO - Running <TaskInstance: yandex-rates-test.insert_data scheduled__2022-08-16T09:00:00+00:00 [running]> on host b232b3e4166c
[2022-08-16 13:00:19,367] {taskinstance.py:1591} INFO - Exporting the following env vars:
AIRFLOW_CTX_DAG_OWNER=***
AIRFLOW_CTX_DAG_ID=yandex-rates-test
AIRFLOW_CTX_TASK_ID=insert_data
AIRFLOW_CTX_EXECUTION_DATE=2022-08-16T09:00:00+00:00
AIRFLOW_CTX_TRY_NUMBER=3
AIRFLOW_CTX_DAG_RUN_ID=scheduled__2022-08-16T09:00:00+00:00
[2022-08-16 13:00:19,412] {logging_mixin.py:115} INFO - rate_date:  2022-08-16
[2022-08-16 13:00:19,413] {logging_mixin.py:115} INFO - value_:  24207.92857100000037
[2022-08-16 13:00:19,461] {taskinstance.py:1909} ERROR - Task failed with exception
Traceback (most recent call last):
  File "/home/airflow/.local/lib/python3.7/site-packages/airflow/operators/python.py", line 171, in execute
    return_value = self.execute_callable()
  File "/home/airflow/.local/lib/python3.7/site-packages/airflow/operators/python.py", line 189, in execute_callable
    return self.python_callable(*self.op_args, **self.op_kwargs)
  File "/opt/airflow/dags/yandex_dag.py", line 72, in insert_data
    pg_conn = get_conn_credentials(dag_variables.get('connection_name'))
  File "/opt/airflow/dags/yandex_dag.py", line 58, in get_conn_credentials
    conn = BaseHook.get_connection(conn_id)
  File "/home/airflow/.local/lib/python3.7/site-packages/airflow/hooks/base.py", line 67, in get_connection
    conn = Connection.get_connection_from_secrets(conn_id)
  File "/home/airflow/.local/lib/python3.7/site-packages/airflow/models/connection.py", line 430, in get_connection_from_secrets
    raise AirflowNotFoundException(f"The conn_id `{conn_id}` isn't defined")
airflow.exceptions.AirflowNotFoundException: The conn_id `test` isn't defined
[2022-08-16 13:00:19,472] {taskinstance.py:1420} INFO - Marking task as FAILED. dag_id=yandex-rates-test, task_id=insert_data, execution_date=20220816T090000, start_date=20220816T130018, end_date=20220816T130019
[2022-08-16 13:00:19,506] {standard_task_runner.py:97} ERROR - Failed to execute job 6 for task insert_data (The conn_id `test` isn't defined; 495)
[2022-08-16 13:00:19,566] {local_task_job.py:156} INFO - Task exited with return code 1
[2022-08-16 13:00:19,679] {local_task_job.py:273} INFO - 0 downstream tasks scheduled from follow-on schedule check
