[2022-08-16 12:57:13,701] {taskinstance.py:1179} INFO - Dependencies all met for <TaskInstance: yandex-rates-test.insert_data scheduled__2022-08-16T09:00:00+00:00 [queued]>
[2022-08-16 12:57:13,745] {taskinstance.py:1179} INFO - Dependencies all met for <TaskInstance: yandex-rates-test.insert_data scheduled__2022-08-16T09:00:00+00:00 [queued]>
[2022-08-16 12:57:13,754] {taskinstance.py:1376} INFO - 
--------------------------------------------------------------------------------
[2022-08-16 12:57:13,755] {taskinstance.py:1377} INFO - Starting attempt 1 of 1
[2022-08-16 12:57:13,762] {taskinstance.py:1378} INFO - 
--------------------------------------------------------------------------------
[2022-08-16 12:57:13,826] {taskinstance.py:1397} INFO - Executing <Task(PythonOperator): insert_data> on 2022-08-16 09:00:00+00:00
[2022-08-16 12:57:13,843] {standard_task_runner.py:52} INFO - Started process 360 to run task
[2022-08-16 12:57:13,884] {standard_task_runner.py:79} INFO - Running: ['***', 'tasks', 'run', 'yandex-rates-test', 'insert_data', 'scheduled__2022-08-16T09:00:00+00:00', '--job-id', '4', '--raw', '--subdir', 'DAGS_FOLDER/yandex_dag.py', '--cfg-path', '/tmp/tmp7m7e3orx', '--error-file', '/tmp/tmpm1a5b7sw']
[2022-08-16 12:57:13,887] {standard_task_runner.py:80} INFO - Job 4: Subtask insert_data
[2022-08-16 12:57:14,337] {task_command.py:371} INFO - Running <TaskInstance: yandex-rates-test.insert_data scheduled__2022-08-16T09:00:00+00:00 [running]> on host b232b3e4166c
[2022-08-16 12:57:14,822] {taskinstance.py:1591} INFO - Exporting the following env vars:
AIRFLOW_CTX_DAG_OWNER=***
AIRFLOW_CTX_DAG_ID=yandex-rates-test
AIRFLOW_CTX_TASK_ID=insert_data
AIRFLOW_CTX_EXECUTION_DATE=2022-08-16T09:00:00+00:00
AIRFLOW_CTX_TRY_NUMBER=1
AIRFLOW_CTX_DAG_RUN_ID=scheduled__2022-08-16T09:00:00+00:00
[2022-08-16 12:57:14,869] {logging_mixin.py:115} INFO - rate_date:  2022-08-16
[2022-08-16 12:57:14,870] {logging_mixin.py:115} INFO - value_:  24207.92857100000037
[2022-08-16 12:57:14,947] {taskinstance.py:1909} ERROR - Task failed with exception
Traceback (most recent call last):
  File "/home/airflow/.local/lib/python3.7/site-packages/airflow/operators/python.py", line 171, in execute
    return_value = self.execute_callable()
  File "/home/airflow/.local/lib/python3.7/site-packages/airflow/operators/python.py", line 189, in execute_callable
    return self.python_callable(*self.op_args, **self.op_kwargs)
  File "/opt/airflow/dags/yandex_dag.py", line 72, in insert_data
    pg_conn = get_conn_credentials(dag_variables.get('connection_name'))
  File "/opt/airflow/dags/yandex_dag.py", line 58, in get_conn_credentials
    conn = BaseHook.get_connection(conn_id)
  File "/home/airflow/.local/lib/python3.7/site-packages/airflow/hooks/base.py", line 67, in get_connection
    conn = Connection.get_connection_from_secrets(conn_id)
  File "/home/airflow/.local/lib/python3.7/site-packages/airflow/models/connection.py", line 430, in get_connection_from_secrets
    raise AirflowNotFoundException(f"The conn_id `{conn_id}` isn't defined")
airflow.exceptions.AirflowNotFoundException: The conn_id `postgre_test_db` isn't defined
[2022-08-16 12:57:14,974] {taskinstance.py:1420} INFO - Marking task as FAILED. dag_id=yandex-rates-test, task_id=insert_data, execution_date=20220816T090000, start_date=20220816T125713, end_date=20220816T125714
[2022-08-16 12:57:15,044] {standard_task_runner.py:97} ERROR - Failed to execute job 4 for task insert_data (The conn_id `postgre_test_db` isn't defined; 360)
[2022-08-16 12:57:15,108] {local_task_job.py:156} INFO - Task exited with return code 1
[2022-08-16 12:57:15,247] {local_task_job.py:273} INFO - 0 downstream tasks scheduled from follow-on schedule check
