[2023-02-04 07:34:47,400] {taskinstance.py:1179} INFO - Dependencies all met for <TaskInstance: yandex-rates-test.get_rates_rows_cnt scheduled__2023-02-04T07:25:00+00:00 [queued]>
[2023-02-04 07:34:47,407] {taskinstance.py:1179} INFO - Dependencies all met for <TaskInstance: yandex-rates-test.get_rates_rows_cnt scheduled__2023-02-04T07:25:00+00:00 [queued]>
[2023-02-04 07:34:47,408] {taskinstance.py:1376} INFO - 
--------------------------------------------------------------------------------
[2023-02-04 07:34:47,409] {taskinstance.py:1377} INFO - Starting attempt 1 of 1
[2023-02-04 07:34:47,409] {taskinstance.py:1378} INFO - 
--------------------------------------------------------------------------------
[2023-02-04 07:34:47,422] {taskinstance.py:1397} INFO - Executing <Task(PythonOperator): get_rates_rows_cnt> on 2023-02-04 07:25:00+00:00
[2023-02-04 07:34:47,426] {standard_task_runner.py:52} INFO - Started process 6101 to run task
[2023-02-04 07:34:47,428] {standard_task_runner.py:79} INFO - Running: ['***', 'tasks', 'run', 'yandex-rates-test', 'get_rates_rows_cnt', 'scheduled__2023-02-04T07:25:00+00:00', '--job-id', '127', '--raw', '--subdir', 'DAGS_FOLDER/yandex_dag_test.py', '--cfg-path', '/tmp/tmpwztf_987', '--error-file', '/tmp/tmp52ntc25i']
[2023-02-04 07:34:47,429] {standard_task_runner.py:80} INFO - Job 127: Subtask get_rates_rows_cnt
[2023-02-04 07:34:47,483] {task_command.py:371} INFO - Running <TaskInstance: yandex-rates-test.get_rates_rows_cnt scheduled__2023-02-04T07:25:00+00:00 [running]> on host 39df186e1726
[2023-02-04 07:34:47,542] {taskinstance.py:1591} INFO - Exporting the following env vars:
AIRFLOW_CTX_DAG_OWNER=***
AIRFLOW_CTX_DAG_ID=yandex-rates-test
AIRFLOW_CTX_TASK_ID=get_rates_rows_cnt
AIRFLOW_CTX_EXECUTION_DATE=2023-02-04T07:25:00+00:00
AIRFLOW_CTX_TRY_NUMBER=1
AIRFLOW_CTX_DAG_RUN_ID=scheduled__2023-02-04T07:25:00+00:00
[2023-02-04 07:34:47,550] {base.py:68} INFO - Using connection ID 'my_db_conn' for task execution.
[2023-02-04 07:34:47,564] {logging_mixin.py:115} INFO - 17
[2023-02-04 07:34:47,564] {taskinstance.py:1909} ERROR - Task failed with exception
Traceback (most recent call last):
  File "/home/airflow/.local/lib/python3.7/site-packages/airflow/operators/python.py", line 171, in execute
    return_value = self.execute_callable()
  File "/home/airflow/.local/lib/python3.7/site-packages/airflow/operators/python.py", line 189, in execute_callable
    return self.python_callable(*self.op_args, **self.op_kwargs)
  File "/opt/airflow/dags/yandex_dag_test.py", line 61, in get_rates_rows_cnt
    Variable.set("rates_rows_cnt", cursor.fetchall()[0][0])
IndexError: list index out of range
[2023-02-04 07:34:47,573] {taskinstance.py:1420} INFO - Marking task as FAILED. dag_id=yandex-rates-test, task_id=get_rates_rows_cnt, execution_date=20230204T072500, start_date=20230204T073447, end_date=20230204T073447
[2023-02-04 07:34:47,582] {standard_task_runner.py:97} ERROR - Failed to execute job 127 for task get_rates_rows_cnt (list index out of range; 6101)
[2023-02-04 07:34:47,601] {local_task_job.py:156} INFO - Task exited with return code 1
[2023-02-04 07:34:47,637] {local_task_job.py:273} INFO - 0 downstream tasks scheduled from follow-on schedule check
