[2022-08-16 17:32:18,849] {taskinstance.py:1179} INFO - Dependencies all met for <TaskInstance: yandex-rates-test.waiting_for_file manual__2022-08-16T17:26:19.248115+00:00 [failed]>
[2022-08-16 17:32:18,894] {taskinstance.py:1179} INFO - Dependencies all met for <TaskInstance: yandex-rates-test.waiting_for_file manual__2022-08-16T17:26:19.248115+00:00 [failed]>
[2022-08-16 17:32:18,907] {taskinstance.py:1376} INFO - 
--------------------------------------------------------------------------------
[2022-08-16 17:32:18,910] {taskinstance.py:1377} INFO - Starting attempt 2 of 1
[2022-08-16 17:32:18,913] {taskinstance.py:1378} INFO - 
--------------------------------------------------------------------------------
[2022-08-16 17:32:19,122] {taskinstance.py:1397} INFO - Executing <Task(FileSensor): waiting_for_file> on 2022-08-16 17:26:19.248115+00:00
[2022-08-16 17:32:19,325] {standard_task_runner.py:52} INFO - Started process 2792 to run task
[2022-08-16 17:32:19,629] {standard_task_runner.py:79} INFO - Running: ['***', 'tasks', 'run', 'yandex-rates-test', 'waiting_for_file', 'manual__2022-08-16T17:26:19.248115+00:00', '--job-id', '76', '--pool', 'default_pool', '--raw', '--subdir', 'DAGS_FOLDER/yandex_dag.py', '--cfg-path', '/tmp/tmpqu17maq5', '--error-file', '/tmp/tmpt4b4b9kn']
[2022-08-16 17:32:19,649] {standard_task_runner.py:80} INFO - Job 76: Subtask waiting_for_file
[2022-08-16 17:32:20,291] {task_command.py:371} INFO - Running <TaskInstance: yandex-rates-test.waiting_for_file manual__2022-08-16T17:26:19.248115+00:00 [running]> on host c6d8e67217b1
[2022-08-16 17:32:21,135] {taskinstance.py:1591} INFO - Exporting the following env vars:
AIRFLOW_CTX_DAG_OWNER=***
AIRFLOW_CTX_DAG_ID=yandex-rates-test
AIRFLOW_CTX_TASK_ID=waiting_for_file
AIRFLOW_CTX_EXECUTION_DATE=2022-08-16T17:26:19.248115+00:00
AIRFLOW_CTX_TRY_NUMBER=2
AIRFLOW_CTX_DAG_RUN_ID=manual__2022-08-16T17:26:19.248115+00:00
[2022-08-16 17:32:21,366] {taskinstance.py:1909} ERROR - Task failed with exception
Traceback (most recent call last):
  File "/home/airflow/.local/lib/python3.7/site-packages/airflow/sensors/base.py", line 277, in execute
    poke_return = self.poke(context)
  File "/home/airflow/.local/lib/python3.7/site-packages/airflow/sensors/filesystem.py", line 55, in poke
    hook = FSHook(self.fs_conn_id)
  File "/home/airflow/.local/lib/python3.7/site-packages/airflow/hooks/filesystem.py", line 38, in __init__
    conn = self.get_connection(conn_id)
  File "/home/airflow/.local/lib/python3.7/site-packages/airflow/hooks/base.py", line 67, in get_connection
    conn = Connection.get_connection_from_secrets(conn_id)
  File "/home/airflow/.local/lib/python3.7/site-packages/airflow/models/connection.py", line 430, in get_connection_from_secrets
    raise AirflowNotFoundException(f"The conn_id `{conn_id}` isn't defined")
airflow.exceptions.AirflowNotFoundException: The conn_id `fs_default2` isn't defined
[2022-08-16 17:32:21,409] {taskinstance.py:1420} INFO - Marking task as FAILED. dag_id=yandex-rates-test, task_id=waiting_for_file, execution_date=20220816T172619, start_date=20220816T173218, end_date=20220816T173221
[2022-08-16 17:32:21,503] {standard_task_runner.py:97} ERROR - Failed to execute job 76 for task waiting_for_file (The conn_id `fs_default2` isn't defined; 2792)
[2022-08-16 17:32:21,620] {local_task_job.py:156} INFO - Task exited with return code 1
[2022-08-16 17:32:21,964] {local_task_job.py:273} INFO - 0 downstream tasks scheduled from follow-on schedule check
